Workbook
Name Beta: Assumptions!$B$47
Name CostOfEquity: Assumptions!$B$48
Name CurrentPrice: DCF!$B$27
Name DilutedShares: Assumptions!$B$58
Name EnterpriseValue: DCF!$B$22
Name EPS_FY25A: IS!$F$43
Name EPS_FY28E: IS!$I$43
Name EPS_FY29E: IS!$J$43
Name EPS_Range: IS!$B$43:$J$43
Name EquityValue: DCF!$B$24
Name ERP: Assumptions!$B$46
Name FCF_FY25A: CFS!$F$21
Name FCF_FY26E: CFS!$G$21
Name FCF_FY28E: CFS!$I$21
Name FCF_FY29E: CFS!$J$21
Name FCF_Range: CFS!$B$21:$J$21
Name FocusYear: Dashboard!$B$18
Name GeographyFilter: Dashboard!$B$24
Name GrossMargin_Range: Ratios!$B$7:$J$7
Name GrossProfit_FY25A: IS!$F$21
Name GrossProfit_FY28E: IS!$I$21
Name GrossProfit_FY29E: IS!$J$21
Name ImpliedPrice: DCF!$B$26
Name NetIncome_FY25A: IS!$F$38
Name NetIncome_FY26E: IS!$G$38
Name NetIncome_FY28E: IS!$I$38
Name NetIncome_FY29E: IS!$J$38
Name NetIncome_Range: IS!$B$38:$J$38
Name NetMargin_Range: Ratios!$B$9:$J$9
Name OpIncome_FY25A: IS!$F$28
Name OpIncome_FY28E: IS!$I$28
Name OpIncome_FY29E: IS!$J$28
Name OpIncome_Range: IS!$B$28:$J$28
Name OpMargin_Range: Ratios!$B$8:$J$8
Name ProductsRev_Range: IS!$B$8:$J$8
Name Revenue_FY25A: IS!$F$14
Name Revenue_FY26E: IS!$G$14
Name Revenue_FY27E: IS!$H$14
Name Revenue_FY28E: IS!$I$14
Name Revenue_FY29E: IS!$J$14
Name Revenue_Range: IS!$B$14:$J$14
Name RiskFreeRate: Assumptions!$B$45
Name Scenario: Dashboard!$B$15
Name SegmentView: Dashboard!$B$21
Name ServicesRev_Range: IS!$B$13:$J$13
Name TerminalGrowth: Assumptions!$B$55
Name Upside: DCF!$B$28
Name WACC: Assumptions!$B$54

Sheet Dashboard
B2: APPLE INC. (AAPL) FINANCIAL DASHBOARD
B3: OVERVIEW OF REVENUE, COSTS, PROFITABILITY & KEY INVESTOR METRICS
C7: 💲 TOTAL REVENUE FY26E | G7: 📊 NET INCOME FY26E | K7: 💰 FREE CASH FLOW FY26E | O7: 🏆 TOP SEGMENT | S7: 📈 DILUTED EPS FY26E
C8: ="$"&TEXT(IS!G14/1000,"0.0")&"B" -> $450.3B | G8: ="$"&TEXT(IS!G38/1000,"0.0")&"B" -> $143.4B | K8: ="$"&TEXT(CFS!G21/1000,"0.0")&"B" -> $144.1B | O8: iPhone | S8: ="$"&TEXT(IS!G43,"0.00") -> $9.94
C9: ="▲ "&TEXT(IS!G14/IS!F14-1,"+0.0%;-0.0%")&" vs FY25A" -> ▲ +8.2% vs FY25A | G9: ="▲ "&TEXT(IS!G38/IS!F38-1,"+0.0%;-0.0%")&" vs FY25A" -> ▲ +28.0% vs FY25A | K9: ="▲ "&TEXT(CFS!G21/CFS!F21-1,"+0.0%;-0.0%")&" vs FY25A" -> ▲ +45.9% vs FY25A | O9: ="$"&TEXT(G80/1000,"0.0")&"B ("&TEXT(G80/G$90,"0.0%")&" of mix)" -> $209.6B (50.4% of mix) | S9: ="▲ "&TEXT(IS!G43/IS!F43-1,"+0.0%;-0.0%")&" vs FY25A" -> ▲ +33.2% vs FY25A
B12: FILTERS & CONTROLS | D12: REVENUE TREND & GROWTH % | M12: $M, FY21A–FY28E | N12: REVENUE BY GEOGRAPHY FY25A | U12: $416B
B14: SCENARIO
B15: =Assumptions!B62 -> Bull | C15: ▾
B17: FOCUS YEAR
B18: FY27E | C18: ▾
B20: SEGMENT VIEW
B21: Services | C21: ▾
B23: GEOGRAPHY
B24: Americas | C24: ▾
B27: Click ▾ to filter
B28: Charts respond live | D28: REVENUE BY SEGMENT FY25A | H28: REVENUE BY GEOGRAPHY FY25A | M28: $B / % mix | N28: TOP 5 PRODUCT LINES BY REVENUE FY25A
H30: REGION | L30: REVENUE | M30: MIX
H31: Americas | K31: =REPT("█",ROUND(M31*40,0)) -> █████████████████ | L31: =IS!F52/1000 -> 178.353 | M31: =IS!F52/IS!F57 -> 0.42856731
H32: Europe | K32: =REPT("█",ROUND(M32*40,0)) -> ███████████ | L32: =IS!F53/1000 -> 111.032 | M32: =IS!F53/IS!F57 -> 0.26680059
H33: Greater China | K33: =REPT("█",ROUND(M33*40,0)) -> ██████ | L33: =IS!F54/1000 -> 64.377 | M33: =IS!F54/IS!F57 -> 0.15469253
H34: Rest of APAC | K34: =REPT("█",ROUND(M34*40,0)) -> ███ | L34: =IS!F56/1000 -> 33.696 | M34: =IS!F56/IS!F57 -> 0.080968664
H35: Japan | K35: =REPT("█",ROUND(M35*40,0)) -> ███ | L35: =IS!F55/1000 -> 28.703 | M35: =IS!F55/IS!F57 -> 0.068970903
H37: Total | L37: =IS!F57/1000 -> 416.161 | M37: =L37/L37 -> 1
D45: P&L CASCADE BY FISCAL YEAR | M45: $M | N45: PROFITABILITY MARGINS TREND | U45: % by FY
D47: LINE ITEM | G47: FY23A | H47: FY24A | I47: FY25A | J47: FY26E | K47: FY27E | L47: FY28E | M47: FY29E
D48: Total Revenue | G48: =IS!D14 -> 383285 | H48: =IS!E14 -> 391035 | I48: =IS!F14 -> 416161 | J48: =IS!G14 -> 450257.23 | K48: =IS!H14 -> 487661.72 | L48: =IS!I14 -> 528747.75 | M48: =IS!J14 -> 573935.26
D49: (-) Cost of Sales | G49: =-(IS!D18+IS!D19) -> -214137 | H49: =-(IS!E18+IS!E19) -> -210352 | I49: =-(IS!F18+IS!F19) -> -220960 | J49: =-(IS!G18+IS!G19) -> -221238.01 | K49: =-(IS!H18+IS!H19) -> -236960.57 | L49: =-(IS!I18+IS!I19) -> -253959.02 | M49: =-(IS!J18+IS!J19) -> -272355.16
D50: Gross Profit | G50: =IS!D21 -> 169148 | H50: =IS!E21 -> 180683 | I50: =IS!F21 -> 195201 | J50: =IS!G21 -> 229019.22 | K50: =IS!H21 -> 250701.15 | L50: =IS!I21 -> 274788.73 | M50: =IS!J21 -> 301580.1
D51: (-) R&D Expense | G51: =-IS!D25 -> -29915 | H51: =-IS!E25 -> -31370 | I51: =-IS!F25 -> -34550 | J51: =-IS!G25 -> -36277.5 | K51: =-IS!H25 -> -38091.375 | L51: =-IS!I25 -> -39995.944 | M51: =-IS!J25 -> -41995.741
D52: (-) SG&A Expense | G52: =-IS!D26 -> -24932 | H52: =-IS!E26 -> -26097 | I52: =-IS!F26 -> -27601 | J52: =-IS!G26 -> -28429.03 | K52: =-IS!H26 -> -29281.901 | L52: =-IS!I26 -> -30160.358 | M52: =-IS!J26 -> -31065.169
D53: Operating Income | G53: =IS!D28 -> 114301 | H53: =IS!E28 -> 123216 | I53: =IS!F28 -> 133050 | J53: =IS!G28 -> 164312.69 | K53: =IS!H28 -> 183327.87 | L53: =IS!I28 -> 204632.43 | M53: =IS!J28 -> 228519.19
D54: (-) Income Tax | G54: =-IS!D36 -> -16741 | H54: =-IS!E36 -> -29749 | I54: =-IS!F36 -> -20719 | J54: =-IS!G36 -> -21425.65 | K54: =-IS!H36 -> -23897.624 | L54: =-IS!I36 -> -26667.216 | M54: =-IS!J36 -> -29772.494
D55: Net Income | G55: =IS!D38 -> 96995 | H55: =IS!E38 -> 93736 | I55: =IS!F38 -> 112010 | J55: =IS!G38 -> 143387.04 | K55: =IS!H38 -> 159930.25 | L55: =IS!I38 -> 178465.22 | M55: =IS!J38 -> 199246.69
D56: Diluted EPS ($) | G56: =IS!D43 -> 6.13 | H56: =IS!E43 -> 6.08 | I56: =IS!F43 -> 7.46 | J56: =IS!G43 -> 9.9358043 | K56: =IS!H43 -> 11.585546 | L56: =IS!I43 -> 13.70132 | M56: =IS!J43 -> 16.436705
D57: Free Cash Flow | G57: =CFS!D21 -> 99584 | H57: =CFS!E21 -> 108807 | I57: =CFS!F21 -> 98767 | J57: =CFS!G21 -> 144092.79 | K57: =CFS!H21 -> 157782.04 | L57: =CFS!I21 -> 195986.33 | M57: =CFS!J21 -> 227302.89
D62: REVENUE BY PRODUCT LINE FY25A | J62: FREE CASH FLOW BY FY | O62: $B | P62: KEY INVESTOR INSIGHTS
P64: 🟢 | Q64: ="Gross margin expanding "&TEXT(Ratios!B7,"0.0%")&" → "&TEXT(Ratios!I7,"0.0%") -> Gross margin expanding 41.8% → 52.0%
B65: Region | C65: FY21A | D65: FY22A | E65: FY23A | F65: FY24A | G65: FY25A | H65: FY26E | I65: FY27E | J65: FY28E | Q65: Services mix shift and own-silicon advantage compounding.
B66: Americas | C66: 153306 | D66: 169658 | E66: 162560 | F66: 167045 | G66: 178353 | H66: =G66*(1+H$71) -> 186378.88 | I66: =H66*(1+I$71) -> 193834.04 | J66: =I66*(1+J$71) -> 200618.23
B67: Europe | C67: 89307 | D67: 95118 | E67: 94294 | F67: 101328 | G67: 111032 | H67: =G67*(1+H$72) -> 117693.92 | I67: =H67*(1+I$72) -> 123578.62 | J67: =I67*(1+J$72) -> 129139.65 | P67: 💡 | Q67: ="Services revenue tripling FY21–FY29: $"&TEXT(C84/1000,"0")&"B → $"&TEXT(K84/1000,"0")&"B" -> Services revenue tripling FY21–FY29: $68B → $153B
...

Sheet Cover
B1: APPLE INC. (NASDAQ: AAPL)
B2: Investment Analyst Model | 3-Statement Forecast + DCF Valuation
B5: MODEL OVERVIEW
B7: Issuer | C7: Apple Inc. (NASDAQ: AAPL)
B8: Sector | C8: Technology — Consumer Electronics & Services
B9: Reporting period | C9: Fiscal years ending last Saturday of September
B10: Historicals | C10: FY2021 – FY2025 (5 years actuals from 10-K filings)
B11: Projections | C11: FY2026E – FY2029E (4 years forecast)
B12: Methodology | C12: Top-down driver-based: segment revenue → gross margin → OpEx → BS roll-forwards
B13: Valuation | C13: DCF using WACC ~8.5%, terminal growth 2.5%, with 5×5 sensitivity table; 4-year explicit forecast + terminal at year 5
B14: Tax assumption | C14: Normalized 15.0% effective rate (FY24 actual elevated by $10.2B EU State Aid charge)
B15: Capital return | C15: ~95% of FCF returned to shareholders via buybacks + dividends (Apple stated policy)
B17: WORKBOOK STRUCTURE
B19: Cover | C19: This page
B20: Assumptions | C20: All forecast drivers — segment growth rates, margins, tax, WACC inputs (BLUE = editable)
B21: IS | C21: Income Statement FY21A–FY29E — top-down build from segment revenue
B22: BS | C22: Balance Sheet FY21A–FY29E — working capital days-based, full roll-forwards
B23: CFS | C23: Cash Flow Statement FY21A–FY29E — indirect method, ties to BS change in cash
B24: Ratios | C24: Profitability, returns, leverage, working capital ratios
B25: DCF | C25: Enterprise value, equity value, implied share price + WACC × g sensitivity
B26: Dashboard | C26: Executive view — KPIs, valuation summary, key charts
B27: Data Refs | C27: All 50+ named ranges documented (name, refers to, used in)
B29: COLOR CONVENTIONS (IB STANDARD)
B31: BLUE | C31: Hardcoded inputs (historicals from 10-K + assumption drivers)
B32: BLACK | C32: Formulas (calculated from inputs and other formulas)
B33: GREEN | C33: Cross-sheet links (pulled from another sheet)
B34: RED | C34: Audit checks (must equal zero) and error flags
B36: DATA SOURCES
B38: 10-K FY2025 | C38: Filed Oct 31, 2025 — covers FY2023A, FY2024A, FY2025A
B39: 10-K FY2022 | C39: Filed Oct 28, 2022 — covers FY2020, FY2021A, FY2022A
B40: SEC EDGAR | C40: https://www.sec.gov/cgi-bin/browse-edgar?action=getcompany&CIK=0000320193
B43: PREPARED BY
B44: Alven Emmanuel | CPA, Financial Data Scientist | Nairobi, Kenya
B45: Fiverr: alvenemmanuel | GitHub: @alvenyuka

Sheet Assumptions
A1: ASSUMPTIONS | Forecast Drivers
A4: USD Millions | B4: FY2021A | C4: FY2022A | D4: FY2023A | E4: FY2024A | F4: FY2025A | G4: FY2026E | H4: FY2027E | I4: FY2028E | J4: FY2029E
B5: Sep 25, 2021 | C5: Sep 24, 2022 | D5: Sep 30, 2023 | E5: Sep 28, 2024 | F5: Sep 27, 2025 | G5: Sep 26, 2026 | H5: Sep 25, 2027 | I5: Sep 30, 2028 | J5: Sep 30, 2029
A7: REVENUE GROWTH DRIVERS | Segment-Level
A8: Products revenue YoY growth | B8: ="" | C8: =IS!C8/IS!B8-1 -> 0.063239764 | D8: =IS!D8/IS!C8-1 -> -0.057286709 | E8: =IS!E8/IS!D8-1 -> -0.010798933 | F8: =IS!F8/IS!E8-1 -> 0.04116107 | G8: =CHOOSE(MATCH(Scenario,{"Bear","Base","Bull"},0),$B$65,$C$65,$D$65) -> 0.061283147 | H8: =CHOOSE(MATCH(Scenario,{"Bear","Base","Bull"},0),$B$65,$C$65,$D$65) -> 0.061283147 | I8: =CHOOSE(MATCH(Scenario,{"Bear","Base","Bull"},0),$B$65,$C$65,$D$65) -> 0.061283147 | J8: =CHOOSE(MATCH(Scenario,{"Bear","Base","Bull"},0),$B$65,$C$65,$D$65) -> 0.061283147
A9: iPhone | C9: =IS!C9/IS!B9-1 -> 0.070405734 | D9: =IS!D9/IS!C9-1 -> -0.023874757 | E9: =IS!E9/IS!D9-1 -> 0.0029912804 | F9: =IS!F9/IS!E9-1 -> 0.041767943 | G9: =CHOOSE(MATCH(Scenario,{"Bear","Base","Bull"},0),$B$66,$C$66,$D$66) -> 0.06 | H9: =CHOOSE(MATCH(Scenario,{"Bear","Base","Bull"},0),$B$66,$C$66,$D$66) -> 0.06 | I9: =CHOOSE(MATCH(Scenario,{"Bear","Base","Bull"},0),$B$66,$C$66,$D$66) -> 0.06 | J9: =CHOOSE(MATCH(Scenario,{"Bear","Base","Bull"},0),$B$66,$C$66,$D$66) -> 0.06
A10: Mac | C10: =IS!C10/IS!B10-1 -> 0.1417164 | D10: =IS!D10/IS!C10-1 -> -0.26930831 | E10: =IS!E10/IS!D10-1 -> 0.021357768 | F10: =IS!F10/IS!E10-1 -> 0.12419957 | G10: =CHOOSE(MATCH(Scenario,{"Bear","Base","Bull"},0),$B$67,$C$67,$D$67) -> 0.08 | H10: =CHOOSE(MATCH(Scenario,{"Bear","Base","Bull"},0),$B$67,$C$67,$D$67) -> 0.08 | I10: =CHOOSE(MATCH(Scenario,{"Bear","Base","Bull"},0),$B$67,$C$67,$D$67) -> 0.08 | J10: =CHOOSE(MATCH(Scenario,{"Bear","Base","Bull"},0),$B$67,$C$67,$D$67) -> 0.08
A11: iPad | C11: =IS!C11/IS!B11-1 -> -0.080660348 | D11: =IS!D11/IS!C11-1 -> -0.033865902 | E11: =IS!E11/IS!D11-1 -> -0.056749117 | F11: =IS!F11/IS!E11-1 -> 0.049786469 | G11: =CHOOSE(MATCH(Scenario,{"Bear","Base","Bull"},0),$B$68,$C$68,$D$68) -> 0.05 | H11: =CHOOSE(MATCH(Scenario,{"Bear","Base","Bull"},0),$B$68,$C$68,$D$68) -> 0.05 | I11: =CHOOSE(MATCH(Scenario,{"Bear","Base","Bull"},0),$B$68,$C$68,$D$68) -> 0.05 | J11: =CHOOSE(MATCH(Scenario,{"Bear","Base","Bull"},0),$B$68,$C$68,$D$68) -> 0.05
A12: Wearables, Home & Accessories | C12: =IS!C12/IS!B12-1 -> 0.074908124 | D12: =IS!D12/IS!C12-1 -> -0.03384981 | E12: =IS!E12/IS!D12-1 -> -0.071276195 | F12: =IS!F12/IS!E12-1 -> -0.035643832 | G12: =CHOOSE(MATCH(Scenario,{"Bear","Base","Bull"},0),$B$69,$C$69,$D$69) -> 0.06 | H12: =CHOOSE(MATCH(Scenario,{"Bear","Base","Bull"},0),$B$69,$C$69,$D$69) -> 0.06 | I12: =CHOOSE(MATCH(Scenario,{"Bear","Base","Bull"},0),$B$69,$C$69,$D$69) -> 0.06 | J12: =CHOOSE(MATCH(Scenario,{"Bear","Base","Bull"},0),$B$69,$C$69,$D$69) -> 0.06
A13: Services revenue YoY growth | B13: ="" | C13: =IS!C13/IS!B13-1 -> 0.14181951 | D13: =IS!D13/IS!C13-1 -> 0.090504166 | E13: =IS!E13/IS!D13-1 -> 0.12874413 | F13: =IS!F13/IS!E13-1 -> 0.13506431 | G13: =CHOOSE(MATCH(Scenario,{"Bear","Base","Bull"},0),$B$70,$C$70,$D$70) -> 0.14 | H13: =CHOOSE(MATCH(Scenario,{"Bear","Base","Bull"},0),$B$70,$C$70,$D$70) -> 0.14 | I13: =CHOOSE(MATCH(Scenario,{"Bear","Base","Bull"},0),$B$70,$C$70,$D$70) -> 0.14 | J13: =CHOOSE(MATCH(Scenario,{"Bear","Base","Bull"},0),$B$70,$C$70,$D$70) -> 0.14
A15: MARGIN DRIVERS | Segment-Level Gross Margins
A16: Products gross margin % | B16: =(IS!B8-IS!B18)/IS!B8 -> 0.35349303 | C16: =(IS!C8-IS!C18)/IS!C8 -> 0.3628348 | D16: =(IS!D8-IS!D18)/IS!D8 -> 0.36500663 | E16: =(IS!E8-IS!E18)/IS!E8 -> 0.37180618 | F16: =(IS!F8-IS!F18)/IS!F8 -> 0.3677065 | G16: =CHOOSE(MATCH(Scenario,{"Bear","Base","Bull"},0),$B$71,$C$71,$D$71) -> 0.405 | H16: =CHOOSE(MATCH(Scenario,{"Bear","Base","Bull"},0),$B$71,$C$71,$D$71) -> 0.405 | I16: =CHOOSE(MATCH(Scenario,{"Bear","Base","Bull"},0),$B$71,$C$71,$D$71) -> 0.405 | J16: =CHOOSE(MATCH(Scenario,{"Bear","Base","Bull"},0),$B$71,$C$71,$D$71) -> 0.405
A17: Services gross margin % | B17: =(IS!B13-IS!B19)/IS!B13 -> 0.69725977 | C17: =(IS!C13-IS!C19)/IS!C13 -> 0.71745447 | D17: =(IS!D13-IS!D19)/IS!D13 -> 0.70827465 | E17: =(IS!E13-IS!E19)/IS!E13 -> 0.73880356 | F17: =(IS!F13-IS!F19)/IS!F13 -> 0.75408124 | G17: =CHOOSE(MATCH(Scenario,{"Bear","Base","Bull"},0),$B$72,$C$72,$D$72) -> 0.78 | H17: =CHOOSE(MATCH(Scenario,{"Bear","Base","Bull"},0),$B$72,$C$72,$D$72) -> 0.78 | I17: =CHOOSE(MATCH(Scenario,{"Bear","Base","Bull"},0),$B$72,$C$72,$D$72) -> 0.78 | J17: =CHOOSE(MATCH(Scenario,{"Bear","Base","Bull"},0),$B$72,$C$72,$D$72) -> 0.78
A19: OPERATING EXPENSE DRIVERS | R&D + SG&A YoY Growth
A20: R&D expense YoY growth | B20: ="" | C20: =IS!C25/IS!B25-1 -> 0.19791001 | D20: =IS!D25/IS!C25-1 -> 0.13957564 | E20: =IS!E25/IS!D25-1 -> 0.048637807 | F20: =IS!F25/IS!E25-1 -> 0.10137074 | G20: =CHOOSE(MATCH(Scenario,{"Bear","Base","Bull"},0),$B$73,$C$73,$D$73) -> 0.05 | H20: =CHOOSE(MATCH(Scenario,{"Bear","Base","Bull"},0),$B$73,$C$73,$D$73) -> 0.05 | I20: =CHOOSE(MATCH(Scenario,{"Bear","Base","Bull"},0),$B$73,$C$73,$D$73) -> 0.05 | J20: =CHOOSE(MATCH(Scenario,{"Bear","Base","Bull"},0),$B$73,$C$73,$D$73) -> 0.05
A21: SG&A expense YoY growth | B21: ="" | C21: =IS!C26/IS!B26-1 -> 0.14203796 | D21: 5 | E21: =IS!E26/IS!D26-1 -> 0.046727098 | F21: =IS!F26/IS!E26-1 -> 0.057631145 | G21: =CHOOSE(MATCH(Scenario,{"Bear","Base","Bull"},0),$B$74,$C$74,$D$74) -> 0.03 | H21: =CHOOSE(MATCH(Scenario,{"Bear","Base","Bull"},0),$B$74,$C$74,$D$74) -> 0.03 | I21: =CHOOSE(MATCH(Scenario,{"Bear","Base","Bull"},0),$B$74,$C$74,$D$74) -> 0.03 | J21: =CHOOSE(MATCH(Scenario,{"Bear","Base","Bull"},0),$B$74,$C$74,$D$74) -> 0.03
A23: OTHER INCOME STATEMENT DRIVERS
A24: Other income / (expense), $M | B24: =IS!B34 -> 258 | C24: =IS!C34 -> -334 | D24: =IS!D34 -> -565 | E24: =IS!E34 -> 269 | F24: =IS!F34 -> -321 | G24: =CHOOSE(MATCH(Scenario,{"Bear","Base","Bull"},0),$B$83,$C$83,$D$83) -> 500 | H24: =CHOOSE(MATCH(Scenario,{"Bear","Base","Bull"},0),$B$83,$C$83,$D$83) -> 500 | I24: =CHOOSE(MATCH(Scenario,{"Bear","Base","Bull"},0),$B$83,$C$83,$D$83) -> 500 | J24: =CHOOSE(MATCH(Scenario,{"Bear","Base","Bull"},0),$B$83,$C$83,$D$83) -> 500
A25: Effective tax rate | B25: =IS!B36/IS!B35 -> 0.13302261 | C25: =IS!C36/IS!C35 -> 0.16204462 | D25: =IS!D36/IS!D35 -> 0.14719174 | E25: =IS!E36/IS!E35 -> 0.24091185 | F25: =IS!F36/IS!F35 -> 0.15610002 | G25: =CHOOSE(MATCH(Scenario,{"Bear","Base","Bull"},0),$B$75,$C$75,$D$75) -> 0.13 | H25: =CHOOSE(MATCH(Scenario,{"Bear","Base","Bull"},0),$B$75,$C$75,$D$75) -> 0.13 | I25: =CHOOSE(MATCH(Scenario,{"Bear","Base","Bull"},0),$B$75,$C$75,$D$75) -> 0.13 | J25: =CHOOSE(MATCH(Scenario,{"Bear","Base","Bull"},0),$B$75,$C$75,$D$75) -> 0.13
A27: BALANCE SHEET DRIVERS | Working Capital Days
A28: Days sales outstanding (DSO) | B28: =BS!C7/IS!B14*365 -> 26.219312 | C28: =BS!D7/IS!C14*365 -> 26.087825 | D28: =BS!E7/IS!D14*365 -> 28.100291 | E28: =BS!F7/IS!E14*365 -> 31.185572 | F28: =BS!G7/IS!F14*365 -> 34.886991 | G28: 30 | H28: 30 | I28: 30 | J28: 30
A29: Days inventory outstanding (DIO) | B29: =BS!C8/IS!B20*365 -> 11.276593 | C29: =BS!D8/IS!C20*365 -> 8.0756981 | D29: =BS!E8/IS!D20*365 -> 10.791292 | E29: =BS!F8/IS!E20*365 -> 12.642571 | F29: =BS!G8/IS!F20*365 -> 9.4454652 | G29: 10 | H29: 10 | I29: 10 | J29: 10
A30: Days payable outstanding (DPO) | B30: =BS!C21/IS!B20*365 -> 93.851071 | C30: =BS!D21/IS!C20*365 -> 104.68528 | D30: =BS!E21/IS!D20*365 -> 106.72147 | E30: =BS!F21/IS!E20*365 -> 119.65848 | F30: =BS!G21/IS!F20*365 -> 115.40052 | G30: 115 | H30: 115 | I30: 115 | J30: 115
A32: Share-based compensation as % of revenue | B32: =CFS!B12/IS!B14 -> 0.021611899 | C32: =CFS!C12/IS!C14 -> 0.022920006 | D32: =CFS!D12/IS!D14 -> 0.028263564 | E32: =CFS!E12/IS!E14 -> 0.029889908 | F32: =CFS!F12/IS!F14 -> 0.030908711 | G32: 0.031 | H32: 0.031 | I32: 0.031 | J32: 0.031
A33: Other current liabilities as % of revenue | B33: =BS!C22/IS!B14 -> 0.12982721 | C33: =BS!D22/IS!C14 -> 0.15430048 | D33: =BS!E22/IS!D14 -> 0.15348631 | E33: =BS!F22/IS!E14 -> 0.20024806 | F33: =BS!G22/IS!F14 -> 0.1957824 | G33: 0.17 | H33: 0.17 | I33: 0.17 | J33: 0.17
A34: Deferred revenue as % of services revenue | B34: =BS!C23/IS!B13 -> 0.11124589 | C34: =BS!D23/IS!C13 -> 0.10126842 | D34: =BS!E23/IS!D13 -> 0.094612676 | E34: =BS!F23/IS!E13 -> 0.085776082 | F34: =BS!G23/IS!F13 -> 0.075569358 | G34: 0.078 | H34: 0.078 | I34: 0.078 | J34: 0.078
A35: Vendor non-trade receivables as % of COGS | B35: =BS!C9/IS!B20 -> 0.11845188 | C35: =BS!D9/IS!C20 -> 0.14649334 | D35: =BS!E9/IS!D20 -> 0.14699468 | E35: =BS!F9/IS!E20 -> 0.15608599 | F35: =BS!G9/IS!F20 -> 0.12874728 | G35: 0.135 | H35: 0.135 | I35: 0.135 | J35: 0.135
A36: CAPEX & DEPRECIATION DRIVERS
A37: CapEx as % of revenue | B37: =-CFS!B19/IS!B14 -> 0.030302036 | C37: =-CFS!C19/IS!C14 -> 0.027155059 | D37: =-CFS!D19/IS!D14 -> 0.028592301 | E37: =-CFS!E19/IS!E14 -> 0.024158963 | F37: =-CFS!F19/IS!F14 -> 0.030553079 | G37: =CHOOSE(MATCH(Scenario,{"Bear","Base","Bull"},0),$B$76,$C$76,$D$76) -> 0.022 | H37: =CHOOSE(MATCH(Scenario,{"Bear","Base","Bull"},0),$B$76,$C$76,$D$76) -> 0.022 | I37: =CHOOSE(MATCH(Scenario,{"Bear","Base","Bull"},0),$B$76,$C$76,$D$76) -> 0.022 | J37: =CHOOSE(MATCH(Scenario,{"Bear","Base","Bull"},0),$B$76,$C$76,$D$76) -> 0.022
A38: Depreciation & amortization, $M | B38: =CFS!B10 -> 11284 | C38: =CFS!C10 -> 11104 | D38: =CFS!D10 -> 11519 | E38: =CFS!E10 -> 11445 | F38: =CFS!F10 -> 11698 | G38: =CHOOSE(MATCH(Scenario,{"Bear","Base","Bull"},0),$B$84,$C$84,$D$84)*IS!G14 -> 11256.431 | H38: =CHOOSE(MATCH(Scenario,{"Bear","Base","Bull"},0),$B$84,$C$84,$D$84)*IS!H14 -> 12191.543 | I38: =CHOOSE(MATCH(Scenario,{"Bear","Base","Bull"},0),$B$84,$C$84,$D$84)*IS!I14 -> 13218.694 | J38: =CHOOSE(MATCH(Scenario,{"Bear","Base","Bull"},0),$B$84,$C$84,$D$84)*IS!J14 -> 14348.381
A40: CAPITAL RETURN POLICY | Per Apple's Stated Plan
A41: Capital return as % of FCF | B41: =(-CFS!B24-CFS!B25)/CFS!B21 -> 1.0805246 | C41: =(-CFS!C24-CFS!C25)/CFS!C21 -> 0.93539298 | D41: =(-CFS!D24-CFS!D25)/CFS!D21 -> 0.92961721 | E41: =(-CFS!E24-CFS!E25)/CFS!E21 -> 1.0126462 | F41: =(-CFS!F24-CFS!F25)/CFS!F21 -> 1.0745694 | G41: =CHOOSE(MATCH(Scenario,{"Bear","Base","Bull"},0),$B$81,$C$81,$D$81) -> 1.05 | H41: =CHOOSE(MATCH(Scenario,{"Bear","Base","Bull"},0),$B$81,$C$81,$D$81) -> 1.05 | I41: =CHOOSE(MATCH(Scenario,{"Bear","Base","Bull"},0),$B$81,$C$81,$D$81) -> 1.05 | J41: =CHOOSE(MATCH(Scenario,{"Bear","Base","Bull"},0),$B$81,$C$81,$D$81) -> 1.05
A42: Dividends as % of capital return | B42: =-CFS!B24/(-CFS!B24-CFS!B25) -> 0.14403911 | C42: =-CFS!C24/(-CFS!C24-CFS!C25) -> 0.14236927 | D42: =-CFS!D24/(-CFS!D24-CFS!D25) -> 0.16230084 | E42: =-CFS!E24/(-CFS!E24-CFS!E25) -> 0.13826089 | F42: =-CFS!F24/(-CFS!F24-CFS!F25) -> 0.14530019 | G42: =CHOOSE(MATCH(Scenario,{"Bear","Base","Bull"},0),$B$82,$C$82,$D$82) -> 0.12 | H42: =CHOOSE(MATCH(Scenario,{"Bear","Base","Bull"},0),$B$82,$C$82,$D$82) -> 0.12 | I42: =CHOOSE(MATCH(Scenario,{"Bear","Base","Bull"},0),$B$82,$C$82,$D$82) -> 0.12 | J42: =CHOOSE(MATCH(Scenario,{"Bear","Base","Bull"},0),$B$82,$C$82,$D$82) -> 0.12
A44: WACC & DCF VALUATION INPUTS
A45: Risk-free rate | B45: =CHOOSE(MATCH(Scenario,{"Bear","Base","Bull"},0),$B$79,$C$79,$D$79) -> 0.04
A46: Equity risk premium | B46: =CHOOSE(MATCH(Scenario,{"Bear","Base","Bull"},0),$B$80,$C$80,$D$80) -> 0.045
A47: Beta (Apple) | B47: =CHOOSE(MATCH(Scenario,{"Bear","Base","Bull"},0),$B$77,$C$77,$D$77) -> 0.95
A48: Cost of equity | B48: =B45+B47*B46 -> 0.08275
A49: Pre-tax cost of debt | B49: 0.04
A50: Tax rate (for WACC) | B50: 0.15
...

Sheet IS
A1: INCOME STATEMENT | FY2021A – FY2029E
A2: Top-down build: segment revenue × segment GM → gross profit → OpEx → operating income → net income
A4: USD Millions | B4: FY2021A | C4: FY2022A | D4: FY2023A | E4: FY2024A | F4: FY2025A | G4: FY2026E | H4: FY2027E | I4: FY2028E | J4: FY2029E
B5: Sep 25, 2021 | C5: Sep 24, 2022 | D5: Sep 30, 2023 | E5: Sep 28, 2024 | F5: Sep 27, 2025 | G5: Sep 26, 2026 | H5: Sep 25, 2027 | I5: Sep 30, 2028 | J5: Sep 30, 2029
A7: REVENUE
A8: Products revenue | B8: 297392 | C8: 316199 | D8: 298085 | E8: 294866 | F8: 307003 | G8: =SUM(G9:G12) -> 325817.11 | H8: =SUM(H9:H12) -> 345799.99 | I8: =SUM(I9:I12) -> 367025.37 | J8: =SUM(J9:J12) -> 389571.74
A9: iPhone | B9: 191973 | C9: 205489 | D9: 200583 | E9: 201183 | F9: 209586 | G9: =F9*(1+Assumptions!G9) -> 222161.16 | H9: =G9*(1+Assumptions!H9) -> 235490.83 | I9: =H9*(1+Assumptions!I9) -> 249620.28 | J9: =I9*(1+Assumptions!J9) -> 264597.5
A10: Mac | B10: 35190 | C10: 40177 | D10: 29357 | E10: 29984 | F10: 33708 | G10: =F10*(1+Assumptions!G10) -> 36404.64 | H10: =G10*(1+Assumptions!H10) -> 39317.011 | I10: =H10*(1+Assumptions!I10) -> 42462.372 | J10: =I10*(1+Assumptions!J10) -> 45859.362
A11: iPad | B11: 31862 | C11: 29292 | D11: 28300 | E11: 26694 | F11: 28023 | G11: =F11*(1+Assumptions!G11) -> 29424.15 | H11: =G11*(1+Assumptions!H11) -> 30895.358 | I11: =H11*(1+Assumptions!I11) -> 32440.125 | J11: =I11*(1+Assumptions!J11) -> 34062.132
A12: Wearables, Home & Accessories | B12: 38367 | C12: 41241 | D12: 39845 | E12: 37005 | F12: 35686 | G12: =F12*(1+Assumptions!G12) -> 37827.16 | H12: =G12*(1+Assumptions!H12) -> 40096.79 | I12: =H12*(1+Assumptions!I12) -> 42502.597 | J12: =I12*(1+Assumptions!J12) -> 45052.753
A13: Services revenue | B13: 68425 | C13: 78129 | D13: 85200 | E13: 96169 | F13: 109158 | G13: =F13*(1+Assumptions!G13) -> 124440.12 | H13: =G13*(1+Assumptions!H13) -> 141861.74 | I13: =H13*(1+Assumptions!I13) -> 161722.38 | J13: =I13*(1+Assumptions!J13) -> 184363.51
A14: Total revenue | B14: =SUM(B9:B13) -> 365817 | C14: =SUM(C9:C13) -> 394328 | D14: =SUM(D9:D13) -> 383285 | E14: =SUM(E9:E13) -> 391035 | F14: =SUM(F9:F13) -> 416161 | G14: =SUM(G9:G13) -> 450257.23 | H14: =SUM(H9:H13) -> 487661.72 | I14: =SUM(I9:I13) -> 528747.75 | J14: =SUM(J9:J13) -> 573935.26
A15: YoY Revenue Growth | B15: - | C15: =(C14-B14)/B14 -> 0.077937876 | D15: =(D14-C14)/C14 -> -0.028004605 | E15: =(E14-D14)/D14 -> 0.020219941 | F15: =(F14-E14)/E14 -> 0.064255118 | G15: =(G14-F14)/F14 -> 0.081930383 | H15: =(H14-G14)/G14 -> 0.083073613 | I15: =(I14-H14)/H14 -> 0.084251084 | J15: =(J14-I14)/I14 -> 0.085461359
A17: COST OF SALES
A18: Cost of products | B18: 192266 | C18: 201471 | D18: 189282 | E18: 185233 | F18: 194116 | G18: =G8*(1-Assumptions!G16) -> 193861.18 | H18: =H8*(1-Assumptions!H16) -> 205750.99 | I18: =I8*(1-Assumptions!I16) -> 218380.1 | J18: =J8*(1-Assumptions!J16) -> 231795.19
A19: Cost of services | B19: 20715 | C19: 22075 | D19: 24855 | E19: 25119 | F19: 26844 | G19: =G13*(1-Assumptions!G17) -> 27376.826 | H19: =H13*(1-Assumptions!H17) -> 31209.582 | I19: =I13*(1-Assumptions!I17) -> 35578.924 | J19: =J13*(1-Assumptions!J17) -> 40559.973
A20: Total cost of sales | B20: =SUM(B18:B19) -> 212981 | C20: =SUM(C18:C19) -> 223546 | D20: =SUM(D18:D19) -> 214137 | E20: =SUM(E18:E19) -> 210352 | F20: =SUM(F18:F19) -> 220960 | G20: =SUM(G18:G19) -> 221238.01 | H20: =SUM(H18:H19) -> 236960.57 | I20: =SUM(I18:I19) -> 253959.02 | J20: =SUM(J18:J19) -> 272355.16
A21: Gross profit | B21: =B14-B20 -> 152836 | C21: =C14-C20 -> 170782 | D21: =D14-D20 -> 169148 | E21: =E14-E20 -> 180683 | F21: =F14-F20 -> 195201 | G21: =G14-G20 -> 229019.22 | H21: =H14-H20 -> 250701.15 | I21: =I14-I20 -> 274788.73 | J21: =J14-J20 -> 301580.1
A22: Gross margin % | B22: =B21/B14 -> 0.4177936 | C22: =C21/C14 -> 0.43309631 | D22: =D21/D14 -> 0.4413113 | E22: =E21/E14 -> 0.4620635 | F22: =F21/F14 -> 0.46905164 | G22: =G21/G14 -> 0.50864086 | H22: =H21/H14 -> 0.51408822 | I22: =I21/I14 -> 0.51969721 | J22: =J21/J14 -> 0.52546013
A24: OPERATING EXPENSES
A25: Research & development | B25: 21914 | C25: 26251 | D25: 29915 | E25: 31370 | F25: 34550 | G25: =F25*(1+Assumptions!G20) -> 36277.5 | H25: =G25*(1+Assumptions!H20) -> 38091.375 | I25: =H25*(1+Assumptions!I20) -> 39995.944 | J25: =I25*(1+Assumptions!J20) -> 41995.741
A26: Selling, general & administrative | B26: 21973 | C26: 25094 | D26: 24932 | E26: 26097 | F26: 27601 | G26: =F26*(1+Assumptions!G21) -> 28429.03 | H26: =G26*(1+Assumptions!H21) -> 29281.901 | I26: =H26*(1+Assumptions!I21) -> 30160.358 | J26: =I26*(1+Assumptions!J21) -> 31065.169
A27: Total operating expenses | B27: =SUM(B25:B26) -> 43887 | C27: =SUM(C25:C26) -> 51345 | D27: =SUM(D25:D26) -> 54847 | E27: =SUM(E25:E26) -> 57467 | F27: =SUM(F25:F26) -> 62151 | G27: =SUM(G25:G26) -> 64706.53 | H27: =SUM(H25:H26) -> 67373.276 | I27: =SUM(I25:I26) -> 70156.302 | J27: =SUM(J25:J26) -> 73060.91
A28: Operating income | B28: =B21-B27 -> 108949 | C28: =C21-C27 -> 119437 | D28: =D21-D27 -> 114301 | E28: =E21-E27 -> 123216 | F28: =F21-F27 -> 133050 | G28: =G21-G27 -> 164312.69 | H28: =H21-H27 -> 183327.87 | I28: =I21-I27 -> 204632.43 | J28: =J21-J27 -> 228519.19
A29: Operating margin % | B29: =B28/B14 -> 0.29782378 | C29: =C28/C14 -> 0.30288744 | D29: =D28/D14 -> 0.29821412 | E29: =E28/E14 -> 0.31510223 | F29: =F28/F14 -> 0.319708 | G29: =G28/G14 -> 0.36493072 | H29: =H28/H14 -> 0.37593246 | I29: =I28/I14 -> 0.38701333 | J29: =J28/J14 -> 0.39816196
A30: (+) Depreciation & Amortization | B30: 11284 | C30: 11104 | D30: 11519 | E30: 11445 | F30: 11698 | G30: =Assumptions!G38 -> 11256.431 | H30: =Assumptions!H38 -> 12191.543 | I30: =Assumptions!I38 -> 13218.694 | J30: =Assumptions!J38 -> 14348.381
A31: EBITDA | B31: =B28+B30 -> 120233 | C31: =C28+C30 -> 130541 | D31: =D28+D30 -> 125820 | E31: =E28+E30 -> 134661 | F31: =F28+F30 -> 144748 | G31: =G28+G30 -> 175569.12 | H31: =H28+H30 -> 195519.42 | I31: =I28+I30 -> 217851.12 | J31: =J28+J30 -> 242867.57
A32: EBITDA Margin % | B32: =B31/B14 -> 0.3286698 | C32: =C31/C14 -> 0.33104674 | D32: =D31/D14 -> 0.32826748 | E32: =E31/E14 -> 0.34437071 | F32: =F31/F14 -> 0.34781731 | G32: =G31/G14 -> 0.38993072 | H32: =H31/H14 -> 0.40093246 | I32: =I31/I14 -> 0.41201333 | J32: =J31/J14 -> 0.42316196
A33: NON-OPERATING & TAXES
A34: Other income / (expense), net | B34: 258 | C34: -334 | D34: -565 | E34: 269 | F34: -321 | G34: =Assumptions!G24 -> 500 | H34: =Assumptions!H24 -> 500 | I34: =Assumptions!I24 -> 500 | J34: =Assumptions!J24 -> 500
A35: Pre-tax income | B35: =B28+B34 -> 109207 | C35: =C28+C34 -> 119103 | D35: =D28+D34 -> 113736 | E35: =E28+E34 -> 123485 | F35: =F28+F34 -> 132729 | G35: =G28+G34 -> 164812.69 | H35: =H28+H34 -> 183827.87 | I35: =I28+I34 -> 205132.43 | J35: =J28+J34 -> 229019.19
A36: Income tax expense | B36: 14527 | C36: 19300 | D36: 16741 | E36: 29749 | F36: 20719 | G36: =G35*Assumptions!G25 -> 21425.65 | H36: =H35*Assumptions!H25 -> 23897.624 | I36: =I35*Assumptions!I25 -> 26667.216 | J36: =J35*Assumptions!J25 -> 29772.494
A37: Effective tax rate | B37: =B36/B35 -> 0.13302261 | C37: =C36/C35 -> 0.16204462 | D37: =D36/D35 -> 0.14719174 | E37: =E36/E35 -> 0.24091185 | F37: =F36/F35 -> 0.15610002 | G37: =G36/G35 -> 0.13 | H37: =H36/H35 -> 0.13 | I37: =I36/I35 -> 0.13 | J37: =J36/J35 -> 0.13
A38: NET INCOME | B38: =B35-B36 -> 94680 | C38: =C35-C36 -> 99803 | D38: =D35-D36 -> 96995 | E38: =E35-E36 -> 93736 | F38: =F35-F36 -> 112010 | G38: =G35-G36 -> 143387.04 | H38: =H35-H36 -> 159930.25 | I38: =I35-I36 -> 178465.22 | J38: =J35-J36 -> 199246.69
A39: Net margin % | B39: =B38/B14 -> 0.25881793 | C39: =C38/C14 -> 0.25309641 | D39: =D38/D14 -> 0.25306234 | E39: =E38/E14 -> 0.23971256 | F39: =F38/F14 -> 0.26915064 | G39: =G38/G14 -> 0.31845584 | H39: =H38/H14 -> 0.32795326 | I39: =I38/I14 -> 0.3375243 | J39: =J38/J14 -> 0.34715883
A41: PER SHARE DATA
A42: Basic EPS ($) | B42: 5.67 | C42: 6.15 | D42: 6.16 | E42: 6.11 | F42: 7.5 | G42: =G38/G44 -> 9.9358043 | H42: =H38/H44 -> 11.585546 | I42: =I38/I44 -> 13.70132 | J42: =J38/J44 -> 16.436705
A43: Diluted EPS ($) | B43: 5.61 | C43: 6.11 | D43: 6.13 | E43: 6.08 | F43: 7.46 | G43: =G38/G44 -> 9.9358043 | H43: =H38/H44 -> 11.585546 | I43: =I38/I44 -> 13.70132 | J43: =J38/J44 -> 16.436705
A44: Diluted shares outstanding (M) | B44: 16864 | C44: 16326 | D44: 15813 | E44: 15409 | F44: 15004 | G44: =F44+CFS!G25/Assumptions!$B$59 -> 14431.347 | H44: =G44+CFS!H25/Assumptions!$B$59 -> 13804.291 | I44: =H44+CFS!I25/Assumptions!$B$59 -> 13025.403 | J44: =I44+CFS!J25/Assumptions!$B$59 -> 12122.058
A45: Dividend per share ($) | B45: 0.85 | C45: 0.91 | D45: 0.95 | E45: 0.99 | F45: 1.06 | G45: =-CFS!G24/G44 -> 1.2580732 | H45: =-CFS!H24/H44 -> 1.4401708 | I45: =-CFS!I24/I44 -> 1.8958551 | J45: =-CFS!J24/J44 -> 2.3626488
...

Sheet BS
B1: APPLE INC. — BALANCE SHEET (FY2021A-FY2029E)
B3: Line Item | C3: FY21A | D3: FY22A | E3: FY23A | F3: FY24A | G3: FY25A | H3: FY26E | I3: FY27E | J3: FY28E | K3: FY29E
B4: CURRENT ASSETS
B5: Cash & cash equivalents | C5: 34940 | D5: 23646 | E5: 29965 | F5: 29943 | G5: 35934 | H5: =CFS!G30 -> 6473.3606 | I5: =CFS!H30 -> -28288.742 | J5: =CFS!I30 -> -48888.058 | K5: =CFS!J30 -> -60253.203
B6: Short-term marketable securities | C6: 27699 | D6: 24658 | E6: 31590 | F6: 35228 | G6: 18763 | H6: =CHOOSE(MATCH(Scenario,{"Bear","Base","Bull"},0),Assumptions!$B$88,Assumptions!$C$88,Assumptions!$D$88) -> 38000 | I6: =CHOOSE(MATCH(Scenario,{"Bear","Base","Bull"},0),Assumptions!$E$88,Assumptions!$F$88,Assumptions!$G$88) -> 40000 | J6: =CHOOSE(MATCH(Scenario,{"Bear","Base","Bull"},0),Assumptions!$H$88,Assumptions!$I$88,Assumptions!$J$88) -> 42000 | K6: =CHOOSE(MATCH(Scenario,{"Bear","Base","Bull"},0),Assumptions!$K$88,Assumptions!$L$88,Assumptions!$M$88) -> 42000
B7: Accounts receivable, net | C7: 26278 | D7: 28184 | E7: 29508 | F7: 33410 | G7: 39777 | H7: =Assumptions!G28*IS!G14/365 -> 37007.444 | I7: =Assumptions!H28*IS!H14/365 -> 40081.786 | J7: =Assumptions!I28*IS!I14/365 -> 43458.719 | K7: =Assumptions!J28*IS!J14/365 -> 47172.761
B8: Inventory | C8: 6580 | D8: 4946 | E8: 6331 | F8: 7286 | G8: 5718 | H8: =Assumptions!G29*IS!G20/365 -> 6061.3153 | I8: =Assumptions!H29*IS!H20/365 -> 6492.0705 | J8: =Assumptions!I29*IS!I20/365 -> 6957.7814 | K8: =Assumptions!J29*IS!J20/365 -> 7461.7852
B9: Vendor non-trade receivables | C9: 25228 | D9: 32748 | E9: 31477 | F9: 32833 | G9: 28448 | H9: =Assumptions!G35*IS!G20 -> 29867.131 | I9: =Assumptions!H35*IS!H20 -> 31989.678 | J9: =Assumptions!I35*IS!I20 -> 34284.468 | K9: =Assumptions!J35*IS!J20 -> 36767.947
B10: Other current assets | C10: 14111 | D10: 21223 | E10: 14695 | F10: 14287 | G10: 19317 | H10: =CHOOSE(MATCH(Scenario,{"Bear","Base","Bull"},0),Assumptions!$B$89,Assumptions!$C$89,Assumptions!$D$89) -> -9400 | I10: =CHOOSE(MATCH(Scenario,{"Bear","Base","Bull"},0),Assumptions!$E$89,Assumptions!$F$89,Assumptions!$G$89) -> -9900 | J10: =CHOOSE(MATCH(Scenario,{"Bear","Base","Bull"},0),Assumptions!$H$89,Assumptions!$I$89,Assumptions!$J$89) -> -10600 | K10: =CHOOSE(MATCH(Scenario,{"Bear","Base","Bull"},0),Assumptions!$K$89,Assumptions!$L$89,Assumptions!$M$89) -> -10600
B11: Total Current Assets | C11: =SUM(C5:C10) -> 134836 | D11: =SUM(D5:D10) -> 135405 | E11: =SUM(E5:E10) -> 143566 | F11: =SUM(F5:F10) -> 152987 | G11: =SUM(G5:G10) -> 147957 | H11: =SUM(H5:H10) -> 108009.25 | I11: =SUM(I5:I10) -> 80374.792 | J11: =SUM(J5:J10) -> 67212.911 | K11: =SUM(K5:K10) -> 62549.29
B13: NON-CURRENT ASSETS
B14: Property, plant & equipment, net | C14: 39440 | D14: 42117 | E14: 43715 | F14: 45680 | G14: 49834 | H14: =G14+Assumptions!G37*IS!G14-Assumptions!G38 -> 48483.228 | I14: =H14+Assumptions!H37*IS!H14-Assumptions!H38 -> 47020.243 | J14: =I14+Assumptions!I37*IS!I14-Assumptions!I38 -> 45434 | K14: =J14+Assumptions!J37*IS!J14-Assumptions!J38 -> 43712.194
B15: Long-term marketable securities | C15: 127877 | D15: 120805 | E15: 100544 | F15: 91479 | G15: 77723 | H15: =H39-H11-H14-H16 -> 49599.294 | I15: =I39-I11-I14-I16 -> 81924.692 | J15: =J39-J11-J14-J16 -> 80412.995 | K15: =K39-K11-K14-K16 -> 80412.995
B16: Other non-current assets | C16: 48849 | D16: 54428 | E16: 64758 | F16: 74834 | G16: 83727 | H16: =CHOOSE(MATCH(Scenario,{"Bear","Base","Bull"},0),Assumptions!$B$90,Assumptions!$C$90,Assumptions!$D$90) -> 118000 | I16: =CHOOSE(MATCH(Scenario,{"Bear","Base","Bull"},0),Assumptions!$E$90,Assumptions!$F$90,Assumptions!$G$90) -> 125000 | J16: =CHOOSE(MATCH(Scenario,{"Bear","Base","Bull"},0),Assumptions!$H$90,Assumptions!$I$90,Assumptions!$J$90) -> 132000 | K16: =CHOOSE(MATCH(Scenario,{"Bear","Base","Bull"},0),Assumptions!$K$90,Assumptions!$L$90,Assumptions!$M$90) -> 132000
B17: Total Non-Current Assets | C17: =SUM(C14:C16) -> 216166 | D17: =SUM(D14:D16) -> 217350 | E17: =SUM(E14:E16) -> 209017 | F17: =SUM(F14:F16) -> 211993 | G17: =SUM(G14:G16) -> 211284 | H17: =SUM(H14:H16) -> 216082.52 | I17: =SUM(I14:I16) -> 253944.94 | J17: =SUM(J14:J16) -> 257846.99 | K17: =SUM(K14:K16) -> 256125.19
B18: TOTAL ASSETS | C18: =C11+C17 -> 351002 | D18: =D11+D17 -> 352755 | E18: =E11+E17 -> 352583 | F18: =F11+F17 -> 364980 | G18: =G11+G17 -> 359241 | H18: =H11+H17 -> 324091.77 | I18: =I11+I17 -> 334319.73 | J18: =J11+J17 -> 325059.91 | K18: =K11+K17 -> 318674.48
B20: CURRENT LIABILITIES
B21: Accounts payable | C21: 54763 | D21: 64115 | E21: 62611 | F21: 68960 | G21: 69860 | H21: =Assumptions!G30*IS!G20/365 -> 69705.125 | I21: =Assumptions!H30*IS!H20/365 -> 74658.811 | J21: =Assumptions!I30*IS!I20/365 -> 80014.486 | K21: =Assumptions!J30*IS!J20/365 -> 85810.53
B22: Other current liabilities | C22: 47493 | D22: 60845 | E22: 58829 | F22: 78304 | G22: 81477 | H22: =Assumptions!G33*IS!G14 -> 76543.729 | I22: =Assumptions!H33*IS!H14 -> 82902.493 | J22: =Assumptions!I33*IS!I14 -> 89887.118 | K22: =Assumptions!J33*IS!J14 -> 97568.993
B23: Deferred revenue | C23: 7612 | D23: 7912 | E23: 8061 | F23: 8249 | G23: 8249 | H23: =Assumptions!G34*IS!G13 -> 9706.3294 | I23: =Assumptions!H34*IS!H13 -> 11065.215 | J23: =Assumptions!I34*IS!I13 -> 12614.346 | K23: =Assumptions!J34*IS!J13 -> 14380.354
B24: Commercial paper | C24: 6000 | D24: 9982 | E24: 5985 | F24: 9967 | G24: 6045 | H24: =CHOOSE(MATCH(Scenario,{"Bear","Base","Bull"},0),Assumptions!$B$91,Assumptions!$C$91,Assumptions!$D$91) -> -4000 | I24: =CHOOSE(MATCH(Scenario,{"Bear","Base","Bull"},0),Assumptions!$E$91,Assumptions!$F$91,Assumptions!$G$91) -> -3300 | J24: =CHOOSE(MATCH(Scenario,{"Bear","Base","Bull"},0),Assumptions!$H$91,Assumptions!$I$91,Assumptions!$J$91) -> -4500 | K24: =CHOOSE(MATCH(Scenario,{"Bear","Base","Bull"},0),Assumptions!$K$91,Assumptions!$L$91,Assumptions!$M$91) -> -4500
B25: Current portion of LT debt | C25: 9613 | D25: 11128 | E25: 9822 | F25: 10912 | G25: 0 | H25: =CHOOSE(MATCH(Scenario,{"Bear","Base","Bull"},0),Assumptions!$B$92,Assumptions!$C$92,Assumptions!$D$92) -> 1500 | I25: =CHOOSE(MATCH(Scenario,{"Bear","Base","Bull"},0),Assumptions!$E$92,Assumptions!$F$92,Assumptions!$G$92) -> 0 | J25: =CHOOSE(MATCH(Scenario,{"Bear","Base","Bull"},0),Assumptions!$H$92,Assumptions!$I$92,Assumptions!$J$92) -> 0 | K25: =CHOOSE(MATCH(Scenario,{"Bear","Base","Bull"},0),Assumptions!$K$92,Assumptions!$L$92,Assumptions!$M$92) -> 0
B26: Total Current Liabilities | C26: =SUM(C21:C25) -> 125481 | D26: =SUM(D21:D25) -> 153982 | E26: =SUM(E21:E25) -> 145308 | F26: =SUM(F21:F25) -> 176392 | G26: =SUM(G21:G25) -> 165631 | H26: =SUM(H21:H25) -> 153455.18 | I26: =SUM(I21:I25) -> 165326.52 | J26: =SUM(J21:J25) -> 178015.95 | K26: =SUM(K21:K25) -> 193259.88
B28: NON-CURRENT LIABILITIES
B29: Long-term debt | C29: 109106 | D29: 98959 | E29: 95281 | F29: 85750 | G29: 78328 | H29: =CHOOSE(MATCH(Scenario,{"Bear","Base","Bull"},0),Assumptions!$B$93,Assumptions!$C$93,Assumptions!$D$93) -> 60000 | I29: =CHOOSE(MATCH(Scenario,{"Bear","Base","Bull"},0),Assumptions!$E$93,Assumptions!$F$93,Assumptions!$G$93) -> 50000 | J29: =CHOOSE(MATCH(Scenario,{"Bear","Base","Bull"},0),Assumptions!$H$93,Assumptions!$I$93,Assumptions!$J$93) -> 40000 | K29: =CHOOSE(MATCH(Scenario,{"Bear","Base","Bull"},0),Assumptions!$K$93,Assumptions!$L$93,Assumptions!$M$93) -> 40000
B30: Other non-current liabilities | C30: 53325 | D30: 49142 | E30: 49848 | F30: 45888 | G30: 41549 | H30: =CHOOSE(MATCH(Scenario,{"Bear","Base","Bull"},0),Assumptions!$B$94,Assumptions!$C$94,Assumptions!$D$94) -> 31000 | I30: =CHOOSE(MATCH(Scenario,{"Bear","Base","Bull"},0),Assumptions!$E$94,Assumptions!$F$94,Assumptions!$G$94) -> 30000 | J30: =CHOOSE(MATCH(Scenario,{"Bear","Base","Bull"},0),Assumptions!$H$94,Assumptions!$I$94,Assumptions!$J$94) -> 29000 | K30: =CHOOSE(MATCH(Scenario,{"Bear","Base","Bull"},0),Assumptions!$K$94,Assumptions!$L$94,Assumptions!$M$94) -> 29000
B31: Total Non-Current Liabilities | C31: =SUM(C29:C30) -> 162431 | D31: =SUM(D29:D30) -> 148101 | E31: =SUM(E29:E30) -> 145129 | F31: =SUM(F29:F30) -> 131638 | G31: =SUM(G29:G30) -> 119877 | H31: =SUM(H29:H30) -> 91000 | I31: =SUM(I29:I30) -> 80000 | J31: =SUM(J29:J30) -> 69000 | K31: =SUM(K29:K30) -> 69000
B32: Total Liabilities | C32: =C26+C31 -> 287912 | D32: =D26+D31 -> 302083 | E32: =E26+E31 -> 290437 | F32: =F26+F31 -> 308030 | G32: =G26+G31 -> 285508 | H32: =H26+H31 -> 244455.18 | I32: =I26+I31 -> 245326.52 | J32: =J26+J31 -> 247015.95 | K32: =K26+K31 -> 262259.88
B34: SHAREHOLDERS' EQUITY
B35: Common stock & paid-in capital | C35: 57365 | D35: 64849 | E35: 73812 | F35: 83276 | G35: 95520 | H35: =G35+CFS!G12 -> 109477.97 | I35: =H35+CFS!H12 -> 124595.49 | J35: =I35+CFS!I12 -> 140986.67 | K35: =J35+CFS!J12 -> 158778.66
B36: Retained earnings | C36: 5562 | D36: -3068 | E36: -214 | F36: -19154 | G36: -22031 | H36: =G36+IS!G38+CFS!G24+CFS!G25 -> -29941.385 | I36: =H36+IS!H38+CFS!H24+CFS!H25 -> -35682.28 | J36: =I36+IS!I38+CFS!I24+CFS!I25 -> -63002.712 | K36: =J36+IS!J38+CFS!J24+CFS!J25 -> -102424.06
B37: Accumulated other comp. inc/(loss) | C37: 163 | D37: -11109 | E37: -11452 | F37: -7172 | G37: 244 | H37: =CHOOSE(MATCH(Scenario,{"Bear","Base","Bull"},0),Assumptions!$B$95,Assumptions!$C$95,Assumptions!$D$95) -> 100 | I37: =CHOOSE(MATCH(Scenario,{"Bear","Base","Bull"},0),Assumptions!$E$95,Assumptions!$F$95,Assumptions!$G$95) -> 80 | J37: =CHOOSE(MATCH(Scenario,{"Bear","Base","Bull"},0),Assumptions!$H$95,Assumptions!$I$95,Assumptions!$J$95) -> 60 | K37: =CHOOSE(MATCH(Scenario,{"Bear","Base","Bull"},0),Assumptions!$K$95,Assumptions!$L$95,Assumptions!$M$95) -> 60
B38: Total Shareholders' Equity | C38: =SUM(C35:C37) -> 63090 | D38: =SUM(D35:D37) -> 50672 | E38: =SUM(E35:E37) -> 62146 | F38: =SUM(F35:F37) -> 56950 | G38: =SUM(G35:G37) -> 73733 | H38: =SUM(H35:H37) -> 79636.589 | I38: =SUM(I35:I37) -> 88993.207 | J38: =SUM(J35:J37) -> 78043.956 | K38: =SUM(K35:K37) -> 56414.601
B39: TOTAL LIABILITIES & EQUITY | C39: =C32+C38 -> 351002 | D39: =D32+D38 -> 352755 | E39: =E32+E38 -> 352583 | F39: =F32+F38 -> 364980 | G39: =G32+G38 -> 359241 | H39: =H32+H38 -> 324091.77 | I39: =I32+I38 -> 334319.73 | J39: =J32+J38 -> 325059.91 | K39: =K32+K38 -> 318674.48
B41: KEY METRICS
B42: Total Debt | C42: =C24+C25+C29 -> 124719 | D42: =D24+D25+D29 -> 120069 | E42: =E24+E25+E29 -> 111088 | F42: =F24+F25+F29 -> 106629 | G42: =G24+G25+G29 -> 84373 | H42: =H24+H25+H29 -> 57500 | I42: =I24+I25+I29 -> 46700 | J42: =J24+J25+J29 -> 35500 | K42: =K24+K25+K29 -> 35500
B43: Net Debt | C43: =C42-C5-C6-C15 -> -65797 | D43: =D42-D5-D6-D15 -> -49040 | E43: =E42-E5-E6-E15 -> -51011 | F43: =F42-F5-F6-F15 -> -50021 | G43: =G42-G5-G6-G15 -> -48047 | H43: =H42-H5-H6-H15 -> -36572.655 | I43: =I42-I5-I6-I15 -> -46935.95 | J43: =J42-J5-J6-J15 -> -38024.937 | K43: =K42-K5-K6-K15 -> -26659.792
B44: Working Capital | C44: =C11-C26 -> 9355 | D44: =D11-D26 -> -18577 | E44: =E11-E26 -> -1742 | F44: =F11-F26 -> -23405 | G44: =G11-G26 -> -17674 | H44: =H11-H26 -> -45445.934 | I44: =I11-I26 -> -84951.728 | J44: =J11-J26 -> -110803.04 | K44: =K11-K26 -> -130710.59
B45: Current Ratio | C45: =C11/C26 -> 1.0745531 | D45: =D11/D26 -> 0.87935603 | E45: =E11/E26 -> 0.98801167 | F45: =F11/F26 -> 0.86731258 | G45: =G11/G26 -> 0.89329292 | H45: =H11/H26 -> 0.70384882 | I45: =I11/I26 -> 0.48615789 | J45: =J11/J26 -> 0.37756679 | K45: =K11/K26 -> 0.32365378
B46: Quick Ratio | C46: =(C11-C8)/C26 -> 1.0221149 | D46: =(D11-D8)/D26 -> 0.84723539 | E46: =(E11-E8)/E26 -> 0.94444215 | F46: =(F11-F8)/F26 -> 0.82600685 | G46: =(G11-G8)/G26 -> 0.8587704 | H46: =(H11-H8)/H26 -> 0.66434989 | I46: =(I11-I8)/I26 -> 0.44688972 | J46: =(J11-J8)/J26 -> 0.33848163 | K46: =(K11-K8)/K26 -> 0.28504367
...

Sheet CFS
A1: CASH FLOW STATEMENT | FY2021A – FY2029E
A2: Indirect method | Reconciles net income to change in cash | Audit check: net change ties to BS
A4: USD Millions | B4: FY2021A | C4: FY2022A | D4: FY2023A | E4: FY2024A | F4: FY2025A | G4: FY2026E | H4: FY2027E | I4: FY2028E | J4: FY2029E
B5: Sep 25, 2021 | C5: Sep 24, 2022 | D5: Sep 30, 2023 | E5: Sep 28, 2024 | F5: Sep 27, 2025 | G5: Sep 26, 2026 | H5: Sep 25, 2027 | I5: Sep 30, 2028 | J5: Sep 30, 2029
A7: Cash & equivalents, beginning | B7: 39789 | C7: =B30 -> 35929 | D7: =C30 -> 24977 | E7: =D30 -> 30737 | F7: =E30 -> 29943 | G7: =F30 -> 35934 | H7: =G30 -> 6473.3606 | I7: =H30 -> -28288.742 | J7: =I30 -> -48888.058
A9: OPERATING ACTIVITIES
A10: Depreciation & amortization | B10: =IS!B30 -> 11284 | C10: =IS!C30 -> 11104 | D10: =IS!D30 -> 11519 | E10: =IS!E30 -> 11445 | F10: =IS!F30 -> 11698 | G10: =Assumptions!G38 -> 11256.431 | H10: =Assumptions!H38 -> 12191.543 | I10: =Assumptions!I38 -> 13218.694 | J10: =Assumptions!J38 -> 14348.381
A11: Net income (from IS) | B11: =IS!B38 -> 94680 | C11: =IS!C38 -> 99803 | D11: =IS!D38 -> 96995 | E11: =IS!E38 -> 93736 | F11: =IS!F38 -> 112010 | G11: =IS!G38 -> 143387.04 | H11: =IS!H38 -> 159930.25 | I11: =IS!I38 -> 178465.22 | J11: =IS!J38 -> 199246.69
A12: Share-based compensation | B12: 7906 | C12: 9038 | D12: 10833 | E12: 11688 | F12: 12863 | G12: =Assumptions!G32*IS!G14 -> 13957.974 | H12: =Assumptions!H32*IS!H14 -> 15117.513 | I12: =Assumptions!I32*IS!I14 -> 16391.18 | J12: =Assumptions!J32*IS!J14 -> 17791.993
A13: Changes in working capital & other | B13: -9832 | C13: 2206 | D13: -8804 | E13: 1385 | F13: -25089 | G13: =-(BS!G7-BS!F7)-(BS!G8-BS!F8)-(BS!G9-BS!F9)-(BS!G10-BS!F10)+(BS!G21-BS!F21)+(BS!G22-BS!F22)+(BS!G23-BS!F23)-(BS!G16-BS!F16)+(BS!G30-BS!F30) -> -14603 | H13: =-(BS!H7-BS!G7)-(BS!H8-BS!G8)-(BS!H9-BS!G9)-(BS!H10-BS!G10)+(BS!H21-BS!G21)+(BS!H22-BS!G22)+(BS!H23-BS!G23)-(BS!H16-BS!G16)+(BS!H30-BS!G30) -> -18728.706 | I13: =-(BS!I7-BS!H7)-(BS!I8-BS!H8)-(BS!I9-BS!H9)-(BS!I10-BS!H10)+(BS!I21-BS!H21)+(BS!I22-BS!H22)+(BS!I23-BS!H23)-(BS!I16-BS!H16)+(BS!I30-BS!H30) -> -456.30797 | J13: =-(BS!K7-BS!J7)-(BS!K8-BS!J8)-(BS!K9-BS!J9)-(BS!K10-BS!J10)+(BS!K21-BS!J21)+(BS!K22-BS!J22)+(BS!K23-BS!J23)-(BS!K16-BS!J16)+(BS!K30-BS!J30) -> 8542.4036
A14: Cash from operating activities | B14: =B10+B11+B12+B13 -> 104038 | C14: =C10+C11+C12+C13 -> 122151 | D14: =D10+D11+D12+D13 -> 110543 | E14: =E10+E11+E12+E13 -> 118254 | F14: =F10+F11+F12+F13 -> 111482 | G14: =G10+G11+G12+G13 -> 153998.45 | H14: =H10+H11+H12+H13 -> 168510.6 | I14: =I10+I11+I12+I13 -> 207618.78 | J14: =J10+J11+J12+J13 -> 239929.47
A16: INVESTING ACTIVITIES
A17: Cash from investing activities | B17: =B19+B20 -> -14545 | C17: =C19+C20 -> -22354 | D17: =D19+D20 -> 3705 | E17: =E19+E20 -> 2935 | F17: =F19+F20 -> 15195 | G17: =G19+G20 -> -9905.6591 | H17: =H19+H20 -> -10728.558 | I17: =I19+I20 -> -11632.451 | J17: =J19+J20 -> -12626.576
A19: Capital expenditures | B19: -11085 | C19: -10708 | D19: -10959 | E19: -9447 | F19: -12715 | G19: =-Assumptions!G37*IS!G14 -> -9905.6591 | H19: =-Assumptions!H37*IS!H14 -> -10728.558 | I19: =-Assumptions!I37*IS!I14 -> -11632.451 | J19: =-Assumptions!J37*IS!J14 -> -12626.576
A20: Other investing | B20: -3460 | C20: -11646 | D20: 14664 | E20: 12382 | F20: 27910 | G20: 0 | H20: 0 | I20: 0 | J20: 0
A21: Free cash flow (CFO − CapEx) | B21: =B14+B19 -> 92953 | C21: =C14+C19 -> 111443 | D21: =D14+D19 -> 99584 | E21: =E14+E19 -> 108807 | F21: =F14+F19 -> 98767 | G21: =G14+G19 -> 144092.79 | H21: =H14+H19 -> 157782.04 | I21: =I14+I19 -> 195986.33 | J21: =J14+J19 -> 227302.89
A23: FINANCING ACTIVITIES
A24: Dividends paid | B24: -14467 | C24: -14841 | D24: -15025 | E24: -15234 | F24: -15421 | G24: =-Assumptions!G42*Assumptions!G41*G21 -> -18155.691 | H24: =-Assumptions!H42*Assumptions!H41*H21 -> -19880.537 | I24: =-Assumptions!I42*Assumptions!I41*I21 -> -24694.278 | J24: =-Assumptions!J42*Assumptions!J41*J21 -> -28640.165
A25: Share repurchases | B25: -85971 | C25: -89402 | D25: -77550 | E25: -94949 | F25: -90711 | G25: =-(1-Assumptions!G42)*Assumptions!G41*G21 -> -133141.74 | H25: =-(1-Assumptions!H42)*Assumptions!H41*H21 -> -145790.61 | I25: =-(1-Assumptions!I42)*Assumptions!I41*I21 -> -181091.37 | J25: =-(1-Assumptions!J42)*Assumptions!J41*J21 -> -210027.87
A26: Net debt repayment & other financing | B26: 7085 | C26: -6506 | D26: -15913 | E26: -11800 | F26: -14554 | G26: =(BS!G24-BS!F24)+(BS!G25-BS!F25)+(BS!G29-BS!F29) -> -22256 | H26: =(BS!H24-BS!G24)+(BS!H25-BS!G25)+(BS!H29-BS!G29) -> -26873 | I26: =(BS!I24-BS!H24)+(BS!I25-BS!H25)+(BS!I29-BS!H29) -> -10800 | J26: =(BS!K24-BS!J24)+(BS!K25-BS!J25)+(BS!K29-BS!J29) -> 0
A27: Cash from financing activities | B27: =SUM(B24:B26) -> -93353 | C27: =SUM(C24:C26) -> -110749 | D27: =SUM(D24:D26) -> -108488 | E27: =SUM(E24:E26) -> -121983 | F27: =SUM(F24:F26) -> -120686 | G27: =SUM(G24:G26) -> -173553.43 | H27: =SUM(H24:H26) -> -192544.15 | I27: =SUM(I24:I26) -> -216585.65 | J27: =SUM(J24:J26) -> -238668.04
A29: Net change in cash | B29: =B14+B17+B27 -> -3860 | C29: =C14+C17+C27 -> -10952 | D29: =D14+D17+D27 -> 5760 | E29: =E14+E17+E27 -> -794 | F29: =F14+F17+F27 -> 5991 | G29: =G14+G17+G27 -> -29460.639 | H29: =H14+H17+H27 -> -34762.102 | I29: =I14+I17+I27 -> -20599.317 | J29: =J14+J17+J27 -> -11365.145
A30: Cash & equivalents, ending | B30: =B7+B29 -> 35929 | C30: =C7+C29 -> 24977 | D30: =D7+D29 -> 30737 | E30: =E7+E29 -> 29943 | F30: =F7+F29 -> 35934 | G30: =G7+G29 -> 6473.3606 | H30: =H7+H29 -> -28288.742 | I30: =I7+I29 -> -48888.058 | J30: =J7+J29 -> -60253.203
A33: FREE CASH FLOW
A34: Free Cash Flow | B34: =B14+B19 -> 92953 | C34: =C14+C19 -> 111443 | D34: =D14+D19 -> 99584 | E34: =E14+E19 -> 108807 | F34: =F14+F19 -> 98767 | G34: =G14+G19 -> 144092.79 | H34: =H14+H19 -> 157782.04 | I34: =I14+I19 -> 195986.33 | J34: =J14+J19 -> 227302.89
A35: FCF Margin % | B35: =B34/IS!B14 -> 0.25409699 | C35: =C34/IS!C14 -> 0.28261498 | D35: =D34/IS!D14 -> 0.25981711 | E35: =E34/IS!E14 -> 0.27825386 | F35: =F34/IS!F14 -> 0.23732882 | G35: =G34/IS!G14 -> 0.32002327 | H35: =H34/IS!H14 -> 0.32354814 | I35: =I34/IS!I14 -> 0.3706613 | J35: =J34/IS!J14 -> 0.39604275
A36: CapEx / Revenue % | B36: =-B19/IS!B14 -> 0.030302036 | C36: =-C19/IS!C14 -> 0.027155059 | D36: =-D19/IS!D14 -> 0.028592301 | E36: =-E19/IS!E14 -> 0.024158963 | F36: =-F19/IS!F14 -> 0.030553079 | G36: =-G19/IS!G14 -> 0.022 | H36: =-H19/IS!H14 -> 0.022 | I36: =-I19/IS!I14 -> 0.022 | J36: =-J19/IS!J14 -> 0.022
A38: Note: BS holds Cash & equivalents (row 8) and current marketable securities (row 9) flat at FY25 levels. Non-current marketable securities (BS row 10) absorbs the projected cash build/draw via the plug formula. Aggregate Cash + securities ties to CFS ending cash.

Sheet Ratios
A1: RATIOS | Profitability, Returns, Liquidity, Leverage
A2: All metrics calculated from IS, BS, and CFS sheets — fully formula-driven
A4: USD Millions | B4: FY2021A | C4: FY2022A | D4: FY2023A | E4: FY2024A | F4: FY2025A | G4: FY2026E | H4: FY2027E | I4: FY2028E | J4: FY2029E
A6: PROFITABILITY MARGINS
A7: Gross margin % | B7: =IS!B21/IS!B14 -> 0.4177936 | C7: =IS!C21/IS!C14 -> 0.43309631 | D7: =IS!D21/IS!D14 -> 0.4413113 | E7: =IS!E21/IS!E14 -> 0.4620635 | F7: =IS!F21/IS!F14 -> 0.46905164 | G7: =IS!G21/IS!G14 -> 0.50864086 | H7: =IS!H21/IS!H14 -> 0.51408822 | I7: =IS!I21/IS!I14 -> 0.51969721 | J7: =IS!J21/IS!J14 -> 0.52546013
A8: Operating margin % | B8: =IS!B28/IS!B14 -> 0.29782378 | C8: =IS!C28/IS!C14 -> 0.30288744 | D8: =IS!D28/IS!D14 -> 0.29821412 | E8: =IS!E28/IS!E14 -> 0.31510223 | F8: =IS!F28/IS!F14 -> 0.319708 | G8: =IS!G28/IS!G14 -> 0.36493072 | H8: =IS!H28/IS!H14 -> 0.37593246 | I8: =IS!I28/IS!I14 -> 0.38701333 | J8: =IS!J28/IS!J14 -> 0.39816196
A9: Net margin % | B9: =IS!B38/IS!B14 -> 0.25881793 | C9: =IS!C38/IS!C14 -> 0.25309641 | D9: =IS!D38/IS!D14 -> 0.25306234 | E9: =IS!E38/IS!E14 -> 0.23971256 | F9: =IS!F38/IS!F14 -> 0.26915064 | G9: =IS!G38/IS!G14 -> 0.31845584 | H9: =IS!H38/IS!H14 -> 0.32795326 | I9: =IS!I38/IS!I14 -> 0.3375243 | J9: =IS!J38/IS!J14 -> 0.34715883
A10: EBITDA margin % | B10: =(IS!B28+CFS!B10)/IS!B14 -> 0.3286698 | C10: =(IS!C28+CFS!C10)/IS!C14 -> 0.33104674 | D10: =(IS!D28+CFS!D10)/IS!D14 -> 0.32826748 | E10: =(IS!E28+CFS!E10)/IS!E14 -> 0.34437071 | F10: =(IS!F28+CFS!F10)/IS!F14 -> 0.34781731 | G10: =(IS!G28+CFS!G10)/IS!G14 -> 0.38993072 | H10: =(IS!H28+CFS!H10)/IS!H14 -> 0.40093246 | I10: =(IS!I28+CFS!I10)/IS!I14 -> 0.41201333 | J10: =(IS!J28+CFS!J10)/IS!J14 -> 0.42316196
A12: GROWTH (YoY)
A13: Revenue growth % | B13: — | C13: =IS!C14/IS!B14-1 -> 0.077937876 | D13: =IS!D14/IS!C14-1 -> -0.028004605 | E13: =IS!E14/IS!D14-1 -> 0.020219941 | F13: =IS!F14/IS!E14-1 -> 0.064255118 | G13: =IS!G14/IS!F14-1 -> 0.081930383 | H13: =IS!H14/IS!G14-1 -> 0.083073613 | I13: =IS!I14/IS!H14-1 -> 0.084251084 | J13: =IS!J14/IS!I14-1 -> 0.085461359
A14: Operating income growth % | B14: — | C14: =IS!C28/IS!B28-1 -> 0.096265225 | D14: =IS!D28/IS!C28-1 -> -0.04300175 | E14: =IS!E28/IS!D28-1 -> 0.077995818 | F14: =IS!F28/IS!E28-1 -> 0.079811063 | G14: =IS!G28/IS!F28-1 -> 0.23496951 | H14: =IS!H28/IS!G28-1 -> 0.11572557 | I14: =IS!I28/IS!H28-1 -> 0.11621014 | J14: =IS!J28/IS!I28-1 -> 0.11673006
A15: Net income growth % | B15: — | C15: =IS!C38/IS!B38-1 -> 0.054108576 | D15: =IS!D38/IS!C38-1 -> -0.028135427 | E15: =IS!E38/IS!D38-1 -> -0.03359967 | F15: =IS!F38/IS!E38-1 -> 0.19495178 | G15: =IS!G38/IS!F38-1 -> 0.28012716 | H15: =IS!H38/IS!G38-1 -> 0.11537449 | I15: =IS!I38/IS!H38-1 -> 0.11589405 | J15: =IS!J38/IS!I38-1 -> 0.11644553
A17: RETURNS
A18: Return on assets (ROA) | B18: =IS!B38/BS!C18 -> 0.26974205 | C18: =IS!C38/BS!D18 -> 0.28292441 | D18: =IS!D38/BS!E18 -> 0.27509835 | E18: =IS!E38/BS!F18 -> 0.25682503 | F18: =IS!F38/BS!G18 -> 0.31179626 | G18: =IS!G38/BS!H18 -> 0.44242728 | H18: =IS!H38/BS!I18 -> 0.47837515 | I18: =IS!I38/BS!J18 -> 0.54902254 | J18: =IS!J38/BS!K18 -> 0.6252358
A19: Return on equity (ROE) | B19: =IS!B38/BS!C38 -> 1.5007133 | C19: =IS!C38/BS!D38 -> 1.9695887 | D19: =IS!D38/BS!E38 -> 1.5607601 | E19: =IS!E38/BS!F38 -> 1.645935 | F19: =IS!F38/BS!G38 -> 1.5191298 | G19: =IS!G38/BS!H38 -> 1.8005171 | H19: =IS!H38/BS!I38 -> 1.7971063 | I19: =IS!I38/BS!J38 -> 2.2867269 | J19: =IS!J38/BS!K38 -> 3.5318284
A20: Return on invested capital | B20: =(IS!B28*(1-Assumptions!$B$50))/(BS!C42+BS!C38) -> 0.49308952 | C20: =(IS!C28*(1-Assumptions!$B$50))/(BS!D42+BS!D38) -> 0.59459327 | D20: =(IS!D28*(1-Assumptions!$B$50))/(BS!E42+BS!E38) -> 0.56083592 | E20: =(IS!E28*(1-Assumptions!$B$50))/(BS!F42+BS!F38) -> 0.64026311 | F20: =(IS!F28*(1-Assumptions!$B$50))/(BS!G42+BS!G38) -> 0.71529543 | G20: =(IS!G28*(1-Assumptions!$B$50))/(BS!H42+BS!H38) -> 1.0184429 | H20: =(IS!H28*(1-Assumptions!$B$50))/(BS!I42+BS!I38) -> 1.1483898 | I20: =(IS!I28*(1-Assumptions!$B$50))/(BS!J42+BS!J38) -> 1.5318963 | J20: =(IS!J28*(1-Assumptions!$B$50))/(BS!K42+BS!K38) -> 2.1132802
A22: LEVERAGE & LIQUIDITY
A23: Debt / Equity | B23: =BS!C42/BS!C38 -> 1.9768426 | C23: =BS!D42/BS!D38 -> 2.3695335 | D23: =BS!E42/BS!E38 -> 1.7875326 | E23: =BS!F42/BS!F38 -> 1.8723266 | F23: =BS!G42/BS!G38 -> 1.1443044 | G23: =BS!H42/BS!H38 -> 0.72202992 | H23: =BS!I42/BS!I38 -> 0.52475915 | I23: =BS!J42/BS!J38 -> 0.45487187 | J23: =BS!K42/BS!K38 -> 0.62926971
A24: Debt / Total capital | B24: =BS!C42/(BS!C42+BS!C38) -> 0.66407361 | C24: =BS!D42/(BS!D42+BS!D38) -> 0.70322301 | D24: =BS!E42/(BS!E42+BS!E38) -> 0.6412598 | E24: =BS!F42/(BS!F42+BS!F38) -> 0.65185018 | F24: =BS!G42/(BS!G42+BS!G38) -> 0.53364831 | G24: =BS!H42/(BS!H42+BS!H38) -> 0.41929 | H24: =BS!I42/(BS!I42+BS!I38) -> 0.34415872 | I24: =BS!J42/(BS!J42+BS!J38) -> 0.31265425 | J24: =BS!K42/(BS!K42+BS!K38) -> 0.38622808
A25: Current ratio | B25: =BS!C11/BS!C26 -> 1.0745531 | C25: =BS!D11/BS!D26 -> 0.87935603 | D25: =BS!E11/BS!E26 -> 0.98801167 | E25: =BS!F11/BS!F26 -> 0.86731258 | F25: =BS!G11/BS!G26 -> 0.89329292 | G25: =BS!H11/BS!H26 -> 0.70384882 | H25: =BS!I11/BS!I26 -> 0.48615789 | I25: =BS!J11/BS!J26 -> 0.37756679 | J25: =BS!K11/BS!K26 -> 0.32365378
A26: Net debt ($M) | B26: =BS!C43 -> -65797 | C26: =BS!D43 -> -49040 | D26: =BS!E43 -> -51011 | E26: =BS!F43 -> -50021 | F26: =BS!G43 -> -48047 | G26: =BS!H43 -> -36572.655 | H26: =BS!I43 -> -46935.95 | I26: =BS!J43 -> -38024.937 | J26: =BS!K43 -> -26659.792
A28: CASH FLOW METRICS
A29: Operating cash flow ($M) | B29: =CFS!B14 -> 104038 | C29: =CFS!C14 -> 122151 | D29: =CFS!D14 -> 110543 | E29: =CFS!E14 -> 118254 | F29: =CFS!F14 -> 111482 | G29: =CFS!G14 -> 153998.45 | H29: =CFS!H14 -> 168510.6 | I29: =CFS!I14 -> 207618.78 | J29: =CFS!J14 -> 239929.47
A30: Free cash flow ($M) | B30: =CFS!B21 -> 92953 | C30: =CFS!C21 -> 111443 | D30: =CFS!D21 -> 99584 | E30: =CFS!E21 -> 108807 | F30: =CFS!F21 -> 98767 | G30: =CFS!G21 -> 144092.79 | H30: =CFS!H21 -> 157782.04 | I30: =CFS!I21 -> 195986.33 | J30: =CFS!J21 -> 227302.89
A31: FCF margin % | B31: =CFS!B21/IS!B14 -> 0.25409699 | C31: =CFS!C21/IS!C14 -> 0.28261498 | D31: =CFS!D21/IS!D14 -> 0.25981711 | E31: =CFS!E21/IS!E14 -> 0.27825386 | F31: =CFS!F21/IS!F14 -> 0.23732882 | G31: =CFS!G21/IS!G14 -> 0.32002327 | H31: =CFS!H21/IS!H14 -> 0.32354814 | I31: =CFS!I21/IS!I14 -> 0.3706613 | J31: =CFS!J21/IS!J14 -> 0.39604275
A32: FCF / Net income | B32: =CFS!B21/IS!B38 -> 0.98175961 | C32: =CFS!C21/IS!C38 -> 1.1166298 | D32: =CFS!D21/IS!D38 -> 1.0266921 | E32: =CFS!E21/IS!E38 -> 1.1607813 | F32: =CFS!F21/IS!F38 -> 0.88176948 | G32: =CFS!G21/IS!G38 -> 1.004922 | H32: =CFS!H21/IS!H38 -> 0.98656785 | I32: =CFS!I21/IS!I38 -> 1.0981766 | J32: =CFS!J21/IS!J38 -> 1.1408114
A33: CapEx / Revenue | B33: =-CFS!B19/IS!B14 -> 0.030302036 | C33: =-CFS!C19/IS!C14 -> 0.027155059 | D33: =-CFS!D19/IS!D14 -> 0.028592301 | E33: =-CFS!E19/IS!E14 -> 0.024158963 | F33: =-CFS!F19/IS!F14 -> 0.030553079 | G33: =-CFS!G19/IS!G14 -> 0.022 | H33: =-CFS!H19/IS!H14 -> 0.022 | I33: =-CFS!I19/IS!I14 -> 0.022 | J33: =-CFS!J19/IS!J14 -> 0.022

Sheet DCF
A1: DCF VALUATION | Discounted Cash Flow
A2: Enterprise value via FCF discounting + Gordon Growth terminal | WACC × g sensitivity table
A4: USD Millions | B4: FY2026E | C4: FY2027E | D4: FY2028E | E4: FY2029E | F4: Terminal
A6: UNLEVERED FREE CASH FLOW BUILD
A7: EBIT (operating income) | B7: =IS!G28 -> 164312.69 | C7: =IS!H28 -> 183327.87 | D7: =IS!I28 -> 204632.43 | E7: =IS!J28 -> 228519.19
A8: × (1 − tax rate) | B8: =1-Assumptions!$B$50 -> 0.85 | C8: =1-Assumptions!$B$50 -> 0.85 | D8: =1-Assumptions!$B$50 -> 0.85 | E8: =1-Assumptions!$B$50 -> 0.85
A9: NOPAT | B9: =B7*B8 -> 139665.79 | C9: =C7*C8 -> 155828.69 | D9: =D7*D8 -> 173937.57 | E9: =E7*E8 -> 194241.31
A10: + Depreciation & amortization | B10: =CFS!G10 -> 11256.431 | C10: =CFS!H10 -> 12191.543 | D10: =CFS!I10 -> 13218.694 | E10: =CFS!J10 -> 14348.381
A11: − CapEx | B11: =CFS!G19 -> -9905.6591 | C11: =CFS!H19 -> -10728.558 | D11: =CFS!I19 -> -11632.451 | E11: =CFS!J19 -> -12626.576
A12: − Change in working capital | B12: =CFS!G13 -> -14603 | C12: =CFS!H13 -> -18728.706 | D12: =CFS!I13 -> -456.30797 | E12: =CFS!J13 -> 8542.4036
A13: Unlevered free cash flow | B13: =B9+B10+B11+B12 -> 126413.56 | C13: =C9+C10+C11+C12 -> 138562.97 | D13: =D9+D10+D11+D12 -> 175067.5 | E13: =E9+E10+E11+E12 -> 204505.52 | F13: =E13*(1+Assumptions!$B$55)/(Assumptions!$B$54-Assumptions!$B$55) -> 4399805.4
A15: Period (years from today) | B15: 1 | C15: 2 | D15: 3 | E15: 4 | F15: 5
A16: Discount factor (at WACC) | B16: =1/(1+Assumptions!$B$54)^B15 -> 0.92775136 | C16: =1/(1+Assumptions!$B$54)^C15 -> 0.86072259 | D16: =1/(1+Assumptions!$B$54)^D15 -> 0.79853656 | E16: =1/(1+Assumptions!$B$54)^E15 -> 0.74084338 | F16: =1/(1+Assumptions!$B$54)^F15 -> 0.68731845
A17: Present value | B17: =B13*B16 -> 117280.35 | C17: =C13*C16 -> 119264.28 | D17: =D13*D16 -> 139797.8 | E17: =E13*E16 -> 151506.56 | F17: =F13*F16 -> 3024067.4
A19: VALUATION SUMMARY
A20: Sum PV of forecast FCFs | B20: =SUM(B17:E17) -> 527848.99
A21: PV of terminal value | B21: =F17 -> 3024067.4
A22: Enterprise value | B22: =B20+B21 -> 3551916.4
A23: − Net debt (FY25) | B23: =BS!F5+BS!F6+BS!F15-BS!F42 -> 50021
A24: Equity value | B24: =B22+B23 -> 3601937.4
A25: ÷ Diluted shares (M) | B25: =Assumptions!$B$58 -> 15004.7
A26: Implied share price | B26: =B24/B25 -> 240.05395
A27: Current share price | B27: =Assumptions!$B$59 -> 232.5
A28: Upside / (downside) | B28: =B26/B27-1 -> 0.032490088
A31: SENSITIVITY | Implied Share Price by WACC × Terminal Growth
A33: WACC ↓ / g → | B33: 0.015 | C33: 0.02 | D33: 0.025 | E33: 0.03 | F33: 0.035
A34: 0.075 | B34: =($B$13/(1+$A34)^1+$C$13/(1+$A34)^2+$D$13/(1+$A34)^3+$E$13/(1+$A34)^4+($E$13*(1+B$33)/($A34-B$33))/(1+$A34)^4+$B$23)/Assumptions!$B$58 -> 211.40632 | C34: =($B$13/(1+$A34)^1+$C$13/(1+$A34)^2+$D$13/(1+$A34)^3+$E$13/(1+$A34)^4+($E$13*(1+C$33)/($A34-C$33))/(1+$A34)^4+$B$23)/Assumptions!$B$58 -> 228.02929 | D34: =($B$13/(1+$A34)^1+$C$13/(1+$A34)^2+$D$13/(1+$A34)^3+$E$13/(1+$A34)^4+($E$13*(1+D$33)/($A34-D$33))/(1+$A34)^4+$B$23)/Assumptions!$B$58 -> 247.97684 | E34: =($B$13/(1+$A34)^1+$C$13/(1+$A34)^2+$D$13/(1+$A34)^3+$E$13/(1+$A34)^4+($E$13*(1+E$33)/($A34-E$33))/(1+$A34)^4+$B$23)/Assumptions!$B$58 -> 272.35718 | F34: =($B$13/(1+$A34)^1+$C$13/(1+$A34)^2+$D$13/(1+$A34)^3+$E$13/(1+$A34)^4+($E$13*(1+F$33)/($A34-F$33))/(1+$A34)^4+$B$23)/Assumptions!$B$58 -> 302.83261
A35: 0.08 | B35: =($B$13/(1+$A35)^1+$C$13/(1+$A35)^2+$D$13/(1+$A35)^3+$E$13/(1+$A35)^4+($E$13*(1+B$33)/($A35-B$33))/(1+$A35)^4+$B$23)/Assumptions!$B$58 -> 194.76737 | C35: =($B$13/(1+$A35)^1+$C$13/(1+$A35)^2+$D$13/(1+$A35)^3+$E$13/(1+$A35)^4+($E$13*(1+C$33)/($A35-C$33))/(1+$A35)^4+$B$23)/Assumptions!$B$58 -> 208.6385 | D35: =($B$13/(1+$A35)^1+$C$13/(1+$A35)^2+$D$13/(1+$A35)^3+$E$13/(1+$A35)^4+($E$13*(1+D$33)/($A35-D$33))/(1+$A35)^4+$B$23)/Assumptions!$B$58 -> 225.03166 | E35: =($B$13/(1+$A35)^1+$C$13/(1+$A35)^2+$D$13/(1+$A35)^3+$E$13/(1+$A35)^4+($E$13*(1+E$33)/($A35-E$33))/(1+$A35)^4+$B$23)/Assumptions!$B$58 -> 244.70344 | F35: =($B$13/(1+$A35)^1+$C$13/(1+$A35)^2+$D$13/(1+$A35)^3+$E$13/(1+$A35)^4+($E$13*(1+F$33)/($A35-F$33))/(1+$A35)^4+$B$23)/Assumptions!$B$58 -> 268.74673
